<?xml version="1.0" ?>
<!-- =================================================================================== -->
<!-- |    This document was autogenerated by xacro from kinectbot.urdf.xacro           | -->
<!-- |    EDITING THIS FILE BY HAND IS NOT RECOMMENDED                                 | -->
<!-- =================================================================================== -->
<!-- XML namespaces -->
<robot name="kinectbot" xmlns:controller="http://playerstage.sourceforge.net/gazebo/xmlschema/#controller" xmlns:interface="http://playerstage.sourceforge.net/gazebo/xmlschema/#interface" xmlns:sensor="http://playerstage.sourceforge.net/gazebo/xmlschema/#sensor" xmlns:xacro="http://ros.org/wiki/xacro">
  <!-- ============================  A Few Color Macros  ============================ -->
  <!-- ============================   A Few Shape Macros  ============================ -->
  <!-- ============================   Link Definitions  ============================ -->
  <link name="base_link">
    <visual>
      <origin rpy="0 0 0" xyz="0 0 0"/>
      <geometry>
        <cylinder length="0.065" radius="0.16"/>
      </geometry>
      <material name="grey1">
        <color rgba="0.75 0.75 0.75 1.0"/>
      </material>
    </visual>
    <collision>
      <origin rpy="0 0 0" xyz="0 0 0"/>
      <geometry>
        <cylinder length="0.065" radius="0.16"/>
      </geometry>
    </collision>
    <inertial>
      <mass value="2.91"/>
      <inertia ixx="0.001" ixy="0.0" ixz="0.0" iyy="0.001" iyz="0.0" izz="0.001"/>
    </inertial>
  </link>
  <gazebo reference="base_link">
    <material>Gazebo/Grey</material>
    <selfCollide>false</selfCollide>
    <turnGravityOff>true</turnGravityOff>
  </gazebo>
  <link name="torso_link">
    <visual>
      <origin rpy="0 0 0" xyz="0 0 0"/>
      <geometry>
        <cylinder length="0.2" radius="0.05"/>
      </geometry>
      <material name="grey2">
        <color rgba="0.6 0.6 0.6 1.0"/>
      </material>
    </visual>
    <collision>
      <origin rpy="0 0 0" xyz="0 0 0"/>
      <geometry>
        <cylinder length="0.2" radius="0.05"/>
      </geometry>
    </collision>
    <inertial>
      <mass value="0.25"/>
      <inertia ixx="0.001" ixy="0.0" ixz="0.0" iyy="0.001" iyz="0.0" izz="0.001"/>
    </inertial>
  </link>
  <gazebo reference="torso_link">
    <material>Gazebo/WhiteEmissive</material>
    <selfCollide>false</selfCollide>
    <turnGravityOff>true</turnGravityOff>
  </gazebo>
  <link name="head_pan_link">
    <visual>
      <origin rpy="0 0 0" xyz="0 0 0"/>
      <geometry>
        <box size="0.05 0.032 0.038"/>
      </geometry>
      <material name="ax12_color">
        <color rgba="0.2 0.2 0.2 1.0"/>
      </material>
    </visual>
    <collision>
      <origin rpy="0 0 0" xyz="0 0 0"/>
      <geometry>
        <box size="0.05 0.032 0.038"/>
      </geometry>
    </collision>
    <inertial>
      <mass value="0.055"/>
      <inertia ixx="0.001" ixy="0.0" ixz="0.0" iyy="0.001" iyz="0.0" izz="0.001"/>
    </inertial>
  </link>
  <gazebo reference="head_pan_link">
    <material>Gazebo/FlatBlack</material>
    <selfCollide>false</selfCollide>
    <turnGravityOff>true</turnGravityOff>
  </gazebo>
  <link name="pan_tilt_bracket">
    <visual>
      <origin rpy="0 0 0" xyz="0 0 0"/>
      <geometry>
        <box size="0.05 0.032 0.005"/>
      </geometry>
      <material name="bracket_color">
        <color rgba="0.9 0.9 0.9 1.0"/>
      </material>
    </visual>
    <collision>
      <origin rpy="0 0 0" xyz="0 0 0"/>
      <geometry>
        <box size="0.05 0.032 0.005"/>
      </geometry>
    </collision>
    <inertial>
      <mass value="0.01"/>
      <inertia ixx="0.001" ixy="0.0" ixz="0.0" iyy="0.001" iyz="0.0" izz="0.001"/>
    </inertial>
  </link>
  <gazebo reference="pan_tilt_bracket">
    <material>Gazebo/WhiteEmissive</material>
    <selfCollide>false</selfCollide>
    <turnGravityOff>true</turnGravityOff>
  </gazebo>
  <link name="head_tilt_link">
    <visual>
      <origin rpy="0 1.57 0" xyz="0 0 0"/>
      <geometry>
        <box size="0.05 0.032 0.038"/>
      </geometry>
      <material name="ax12_color">
        <color rgba="0.2 0.2 0.2 1.0"/>
      </material>
    </visual>
    <collision>
      <origin rpy="0 1.57 0" xyz="0 0 0"/>
      <geometry>
        <box size="0.05 0.032 0.038"/>
      </geometry>
    </collision>
    <inertial>
      <mass value="0.055"/>
      <inertia ixx="0.001" ixy="0.0" ixz="0.0" iyy="0.001" iyz="0.0" izz="0.001"/>
    </inertial>
  </link>
  <gazebo reference="head_tilt_link">
    <material>Gazebo/FlatBlack</material>
    <selfCollide>false</selfCollide>
    <turnGravityOff>true</turnGravityOff>
  </gazebo>
  <link name="neck_link">
    <visual>
      <origin rpy="0 0 0" xyz="0 0 0.02"/>
      <geometry>
        <box size="0.028 0.048 0.068"/>
      </geometry>
      <material name="bracket_color">
        <color rgba="0.9 0.9 0.9 1.0"/>
      </material>
    </visual>
    <collision>
      <origin rpy="0 0 0" xyz="0 0 0.02"/>
      <geometry>
        <box size="0.028 0.048 0.068"/>
      </geometry>
    </collision>
    <inertial>
      <mass value="0.05"/>
      <inertia ixx="0.001" ixy="0.0" ixz="0.0" iyy="0.001" iyz="0.0" izz="0.001"/>
    </inertial>
  </link>
  <gazebo reference="neck_link">
    <material>Gazebo/WhiteEmissive</material>
    <selfCollide>false</selfCollide>
    <turnGravityOff>true</turnGravityOff>
  </gazebo>
  <link name="head_base_link">
    <visual>
      <origin rpy="0 0 0" xyz="0 0 0"/>
      <geometry>
        <box size="0.06 0.08 0.02"/>
      </geometry>
      <material name="black">
        <color rgba="0.1 0.1 0.1 1.0"/>
      </material>
    </visual>
    <collision>
      <origin rpy="0 0 0" xyz="0 0 0"/>
      <geometry>
        <box size="0.06 0.08 0.02"/>
      </geometry>
    </collision>
    <inertial>
      <mass value="0.1"/>
      <inertia ixx="0.001" ixy="0.0" ixz="0.0" iyy="0.001" iyz="0.0" izz="0.001"/>
    </inertial>
  </link>
  <gazebo reference="head_base_link">
    <material>Gazebo/FlatBlack</material>
    <selfCollide>false</selfCollide>
    <turnGravityOff>true</turnGravityOff>
  </gazebo>
  <link name="head_post_link">
    <visual>
      <origin rpy="0 0 0" xyz="0 0 0"/>
      <geometry>
        <cylinder length="0.012" radius="0.005"/>
      </geometry>
      <material name="grey3">
        <color rgba="0.8 0.8 0.8 1.0"/>
      </material>
    </visual>
    <collision>
      <origin rpy="0 0 0" xyz="0 0 0"/>
      <geometry>
        <cylinder length="0.012" radius="0.005"/>
      </geometry>
    </collision>
    <inertial>
      <mass value="0.1"/>
      <inertia ixx="0.001" ixy="0.0" ixz="0.0" iyy="0.001" iyz="0.0" izz="0.001"/>
    </inertial>
  </link>
  <gazebo reference="head_post_link">
    <material>Gazebo/WhiteEmissive</material>
    <selfCollide>false</selfCollide>
    <turnGravityOff>true</turnGravityOff>
  </gazebo>
  <link name="head_link">
    <visual>
      <origin rpy="0 0 0" xyz="0 0 0"/>
      <geometry>
        <box size="0.06 0.26 0.035"/>
      </geometry>
      <material name="black">
        <color rgba="0.1 0.1 0.1 1.0"/>
      </material>
    </visual>
    <collision>
      <origin rpy="0 0 0" xyz="0 0 0"/>
      <geometry>
        <box size="0.06 0.26 0.035"/>
      </geometry>
    </collision>
    <inertial>
      <mass value="0.8"/>
      <inertia ixx="0.001" ixy="0.0" ixz="0.0" iyy="0.001" iyz="0.0" izz="0.001"/>
    </inertial>
  </link>
  <gazebo reference="head_link">
    <material>Gazebo/FlatBlack</material>
    <selfCollide>false</selfCollide>
    <turnGravityOff>true</turnGravityOff>
  </gazebo>
  <link name="left_eye_link">
    <visual>
      <origin rpy="0 1.57 0" xyz="0 0 0"/>
      <geometry>
        <cylinder length="0.01" radius="0.01"/>
      </geometry>
      <material name="grey3">
        <color rgba="0.8 0.8 0.8 1.0"/>
      </material>
    </visual>
    <collision>
      <origin rpy="0 1.57 0" xyz="0 0 0"/>
      <geometry>
        <cylinder length="0.01" radius="0.01"/>
      </geometry>
    </collision>
    <inertial>
      <mass value="0.001"/>
      <inertia ixx="0.001" ixy="0.0" ixz="0.0" iyy="0.001" iyz="0.0" izz="0.001"/>
    </inertial>
  </link>
  <gazebo reference="left_eye_link">
    <material>Gazebo/WhiteEmissive</material>
    <selfCollide>false</selfCollide>
    <turnGravityOff>true</turnGravityOff>
  </gazebo>
  <link name="right_eye_link">
    <visual>
      <origin rpy="0 1.57 0" xyz="0 0 00"/>
      <geometry>
        <cylinder length="0.01" radius="0.01"/>
      </geometry>
      <material name="grey3">
        <color rgba="0.8 0.8 0.8 1.0"/>
      </material>
    </visual>
    <collision>
      <origin rpy="0 1.57 0" xyz="0 0 00"/>
      <geometry>
        <cylinder length="0.01" radius="0.01"/>
      </geometry>
    </collision>
    <inertial>
      <mass value="0.001"/>
      <inertia ixx="0.001" ixy="0.0" ixz="0.0" iyy="0.001" iyz="0.0" izz="0.001"/>
    </inertial>
  </link>
  <gazebo reference="right_eye_link">
    <material>Gazebo/WhiteEmissive</material>
    <selfCollide>false</selfCollide>
    <turnGravityOff>true</turnGravityOff>
  </gazebo>
  <link name="hair_link">
    <visual>
      <origin rpy="0 0 0" xyz="0 0 0"/>
      <geometry>
        <box size="0.005 0.04 0.05"/>
      </geometry>
      <material name="grey2">
        <color rgba="0.6 0.6 0.6 1.0"/>
      </material>
    </visual>
    <collision>
      <origin rpy="0 0 0" xyz="0 0 0"/>
      <geometry>
        <box size="0.005 0.04 0.05"/>
      </geometry>
    </collision>
    <inertial>
      <mass value="0.05"/>
      <inertia ixx="0.001" ixy="0.0" ixz="0.0" iyy="0.001" iyz="0.0" izz="0.001"/>
    </inertial>
  </link>
  <gazebo reference="hair_link">
    <material>Gazebo/WhiteEmissive</material>
    <selfCollide>false</selfCollide>
    <turnGravityOff>true</turnGravityOff>
  </gazebo>
  <!-- =================== Joint Definitions ==================== -->
  <joint name="torso_joint" type="fixed">
    <parent link="base_link"/>
    <child link="torso_link"/>
    <origin rpy="0 0 0" xyz="0 0 0.1325"/>
  </joint>
  <joint name="head_pan_servo" type="fixed">
    <parent link="torso_link"/>
    <child link="head_pan_link"/>
    <origin rpy="0 0 0" xyz="0 0 0.119"/>
  </joint>
  <joint name="pan_tilt_bracket" type="fixed">
    <parent link="head_pan_link"/>
    <child link="pan_tilt_bracket"/>
    <origin rpy="0 0 0" xyz="0 0 0.0215"/>
  </joint>
  <joint name="head_pan_joint" type="revolute">
    <parent link="pan_tilt_bracket"/>
    <child link="head_tilt_link"/>
    <origin rpy="0 0 0" xyz="0 0 0.0275"/>
    <axis xyz="0 0 1"/>
    <limit effort="10" lower="-3.1416" upper="3.1416" velocity="3"/>
    <dynamics damping="0.0"/>
  </joint>
  <joint name="head_tilt_joint" type="revolute">
    <parent link="head_tilt_link"/>
    <child link="neck_link"/>
    <origin rpy="0 0 0" xyz="0 0 0.02"/>
    <axis xyz="0 -1 0"/>
    <limit effort="10" lower="-1.57" upper="1.57" velocity="3"/>
    <dynamics damping="0.0"/>
  </joint>
  <joint name="neck_joint" type="fixed">
    <parent link="neck_link"/>
    <child link="head_base_link"/>
    <origin rpy="0 0 0" xyz="0 0 0.064"/>
  </joint>
  <joint name="head_base_joint" type="fixed">
    <parent link="head_base_link"/>
    <child link="head_post_link"/>
    <origin rpy="0 0 0" xyz="0 0 0.016"/>
  </joint>
  <joint name="head_joint" type="fixed">
    <parent link="head_post_link"/>
    <child link="head_link"/>
    <origin rpy="0 0 0" xyz="0 0 0.0235"/>
  </joint>
  <joint name="left_eye_joint" type="fixed">
    <parent link="head_link"/>
    <child link="left_eye_link"/>
    <origin rpy="0 0 0" xyz="0.026 0.05 0"/>
  </joint>
  <joint name="right_eye_joint" type="fixed">
    <parent link="head_link"/>
    <child link="right_eye_link"/>
    <origin rpy="0 0 0" xyz="0.026 -0.05 0"/>
  </joint>
  <joint name="hair_joint" type="fixed">
    <parent link="head_link"/>
    <child link="hair_link"/>
    <origin rpy="0 0 0" xyz="-0.025 0 0.0425"/>
  </joint>
  <gazebo reference="kinectbot">
  	</gazebo>
</robot>

