<?xml version="1.0"?>

<!-- XML namespaces -->
<robot xmlns:sensor="http://playerstage.sourceforge.net/gazebo/xmlschema/#sensor"
       xmlns:controller="http://playerstage.sourceforge.net/gazebo/xmlschema/#controller"
       xmlns:interface="http://playerstage.sourceforge.net/gazebo/xmlschema/#interface"
       xmlns:xacro="http://ros.org/wiki/xacro" 
	   name="kinectbot">
	   
 	<!-- ============================  A Few Color Macros  ============================ -->
	
	<xacro:macro name="black">
		<material name="black">
			<color rgba="0.1 0.1 0.1 1.0"/>
		</material>
	</xacro:macro>
	
	<xacro:macro name="white">
		<material name="white">
			<color rgba="1.0 1.0 1.0 1.0"/>
		</material>
	</xacro:macro>
	
	<xacro:macro name="grey1">
		<material name="grey1">
			<color rgba="0.75 0.75 0.75 1.0"/>
		</material>
	</xacro:macro>
	
	<xacro:macro name="grey2">
		<material name="grey2">
			<color rgba="0.6 0.6 0.6 1.0"/>
		</material>
	</xacro:macro>
	
	<xacro:macro name="grey3">
		<material name="grey3">
			<color rgba="0.8 0.8 0.8 1.0"/>
		</material>
	</xacro:macro>

	<xacro:macro name="ax12_color">
		<material name="ax12_color">
			<color rgba="0.2 0.2 0.2 1.0"/>
		</material>
	</xacro:macro>
	
	<xacro:macro name="bracket_color">
		<material name="bracket_color">
			<color rgba="0.9 0.9 0.9 1.0"/>
		</material>
	</xacro:macro>
	
 	<!-- ============================   A Few Shape Macros  ============================ -->
	
	<xacro:macro name="ax12" params="name xyz rpy">
		<link name="${name}">
			<visual>
				<origin xyz="${xyz}" rpy="${rpy}" />
				<geometry>
					<box size="0.05 0.032 0.038" />
				</geometry>
				<xacro:ax12_color />
             </visual>
             <collision>
				<origin xyz="${xyz}" rpy="${rpy}" />
					<geometry>
						<box size="0.05 0.032 0.038" />
					</geometry>
             </collision>
             <xacro:default_inertial mass="0.055" />   
        </link>
        <xacro:default_gazebo name="${name}" material="Gazebo/FlatBlack" />
	</xacro:macro>
	
	<xacro:macro name="bracket1" params="name xyz rpy">
		<link name="${name}">
			<visual>
				<origin xyz="${xyz}" rpy="${rpy}" />
				<geometry>
					<box size="0.05 0.025 0.038" />	
				</geometry>
				<xacro:bracket_color />
             </visual>
             <collision>
				<origin xyz="${xyz}" rpy="${rpy}" />
					<geometry>
						<box size="0.05 0.025 0.038" />
					</geometry>
             </collision>
             <xacro:default_inertial mass="0.02" />   
        </link>
        <xacro:default_gazebo name="${name}" material="Gazebo/WhiteEmissive" />
	</xacro:macro>
	
	<xacro:macro name="bracket2" params="name xyz rpy">
		<link name="${name}">
			<visual>
				<origin xyz="${xyz}" rpy="${rpy}" />
				<geometry>
					<box size="0.05 0.032 0.005" />	
				</geometry>
				<xacro:bracket_color />
             </visual>
             <collision>
				<origin xyz="${xyz}" rpy="${rpy}" />
					<geometry>
					<box size="0.05 0.032 0.005" />	
					</geometry>
             </collision>
             <xacro:default_inertial mass="0.01" />   
        </link>
        <xacro:default_gazebo name="${name}" material="Gazebo/WhiteEmissive" />
	</xacro:macro>
	
	<xacro:macro name="my_box" params="name lwh xyz rpy mass material *rviz_color">
		<link name="${name}">
			<visual>
				<origin xyz="${xyz}" rpy="${rpy}" />
				<geometry>
					<box size="${lwh}" />
				</geometry>
			    <xacro:insert_block name="rviz_color" />             
             </visual>
             <collision>
				<origin xyz="${xyz}" rpy="${rpy}" />
					<geometry>
						<box size="${lwh}" />
					</geometry>
             </collision>
             <xacro:default_inertial mass="${mass}" />   
        </link>
        <xacro:default_gazebo name="${name}" material="${material}" />
	</xacro:macro>

	<xacro:macro name="my_cylinder" params="name l r xyz rpy mass material *rviz_color">
		<link name="${name}">
			<visual>	
				<origin xyz="${xyz}" rpy="${rpy}" />
				<geometry>
					<cylinder length="${l}" radius="${r}" />
				</geometry>
            	<xacro:insert_block name="rviz_color" />
            </visual>
            <collision>
				<origin xyz="${xyz}" rpy="${rpy}" />
					<geometry>
						<cylinder length="${l}" radius="${r}" />
					</geometry>
            </collision>
            <xacro:default_inertial mass="${mass}" />
        </link>
        <xacro:default_gazebo name="${name}" material="${material}" />
	</xacro:macro>

    <xacro:macro name="default_inertial" params="mass">
		<inertial>
			<mass value="${mass}" />
			<inertia ixx="0.001" ixy="0.0" ixz="0.0"
                     iyy="0.001" iyz="0.0"
                     izz="0.001" />                     
			</inertial>
    </xacro:macro>
    
    <xacro:macro name="default_gazebo" params="name material">
 		<gazebo reference="${name}">
			<material>${material}</material>
			<selfCollide>false</selfCollide>
			<turnGravityOff>true</turnGravityOff>
		</gazebo>
    </xacro:macro>
    
 	<!-- ============================   Link Definitions  ============================ -->

	<xacro:my_cylinder name="base_link" l="0.065" r="0.16" xyz="0 0 0" rpy="0 0 0" mass="2.91" material="Gazebo/Grey">
		<xacro:grey1 />
	</xacro:my_cylinder>
	
	<xacro:my_cylinder name="torso_link" l="0.20" r="0.05" xyz="0 0 0" rpy="0 0 0" mass="0.250" material="Gazebo/WhiteEmissive">
		<xacro:grey2 />
	</xacro:my_cylinder>
	
	<xacro:ax12 name="head_pan_link" xyz="0 0 0" rpy="0 0 0">
	</xacro:ax12>
	
	<xacro:bracket2 name="pan_tilt_bracket" xyz="0 0 0" rpy="0 0 0">
	</xacro:bracket2>
	
	<xacro:ax12 name="head_tilt_link" xyz="0 0 0" rpy="0 1.57 0">
	</xacro:ax12>
	
	<xacro:my_box name="neck_link" lwh="0.028 0.048 0.068" xyz="0 0 0.02" rpy="0 0 0" mass="0.05" material="Gazebo/WhiteEmissive">
		<xacro:bracket_color />
	</xacro:my_box>
	
	<xacro:my_box name="head_base_link" lwh="0.06 0.08 0.02" xyz="0 0 0" rpy="0 0 0" mass="0.1" material="Gazebo/FlatBlack">
		<xacro:black />
	</xacro:my_box>
	
	<xacro:my_cylinder name="head_post_link" l="0.012" r="0.005" xyz="0 0 0" rpy="0 0 0" mass="0.1" material="Gazebo/WhiteEmissive">
		<xacro:grey3 />
	</xacro:my_cylinder>
	
	<xacro:my_box name="head_link" lwh="0.06 0.26 0.035" xyz="0 0 0" rpy="0 0 0" mass="0.8" material="Gazebo/FlatBlack">
		<xacro:black />
	</xacro:my_box>
	
	<xacro:my_cylinder name="left_eye_link" l="0.01" r="0.01" xyz="0 0 0" rpy="0 1.57 0" mass="0.001" material="Gazebo/WhiteEmissive">
		<xacro:grey3 />
	</xacro:my_cylinder>
	
	<xacro:my_cylinder name="right_eye_link" l="0.01" r="0.01" xyz="0 0 00" rpy="0 1.57 0" mass="0.001" material="Gazebo/WhiteEmissive">
		<xacro:grey3 />
	</xacro:my_cylinder>
	
	<xacro:my_box name="hair_link" lwh="0.005 0.04 0.05" xyz="0 0 0" rpy="0 0 0" mass="0.05" material="Gazebo/WhiteEmissive">
		<xacro:grey2 />
	</xacro:my_box>
	
	<!-- =================== Joint Definitions ==================== -->

	<joint name="torso_joint" type="fixed">
    	<parent link="base_link" />
    	<child link="torso_link" />
    	<origin xyz="0 0 0.1325" rpy="0 0 0" />
	</joint>
  
	<joint name="head_pan_servo" type="fixed">
    	<parent link="torso_link" />
    	<child link="head_pan_link" />
    	<origin xyz="0 0 0.119" rpy="0 0 0" />
	</joint>
	
	<joint name="pan_tilt_bracket" type="fixed">
    	<parent link="head_pan_link" />
    	<child link="pan_tilt_bracket" />
    	<origin xyz="0 0 0.0215" rpy="0 0 0" />
	</joint>
	
	<joint name="head_pan_joint" type="revolute">
    	<parent link="pan_tilt_bracket" />
    	<child link="head_tilt_link" />
    	<origin xyz="0 0 0.0275" rpy="0 0 0" />
    	<axis xyz="0 0 1" />
    	<limit lower="-3.1416" upper="3.1416" effort="10" velocity="3" />
      	<dynamics damping="0.0"/>
	</joint>
  	
 	<joint name="head_tilt_joint" type="revolute">
    	<parent link="head_tilt_link" />
    	<child link="neck_link" />
    	<origin xyz="0 0 0.02" rpy="0 0 0" />
    	<axis xyz="0 -1 0" />
    	<limit lower="-1.57" upper="1.57" effort="10" velocity="3" />
      	<dynamics damping="0.0"/>
	</joint>
  	
 	<joint name="neck_joint" type="fixed">
    	<parent link="neck_link" />
    	<child link="head_base_link" />
    	<origin xyz="0 0 0.064" rpy="0 0 0" />
	</joint>
	
	<joint name="head_base_joint" type="fixed">
    	<parent link="head_base_link" />
    	<child link="head_post_link" />
    	<origin xyz="0 0 0.016" rpy="0 0 0" />
	</joint>
	
	<joint name="head_joint" type="fixed">
    	<parent link="head_post_link" />
    	<child link="head_link" />
    	<origin xyz="0 0 0.0235" rpy="0 0 0" />
	</joint>
	
	<joint name="left_eye_joint" type="fixed">
    	<parent link="head_link" />
    	<child link="left_eye_link" />
    	<origin xyz="0.026 0.05 0" rpy="0 0 0" />
	</joint>
	
	<joint name="right_eye_joint" type="fixed">
    	<parent link="head_link" />
    	<child link="right_eye_link" />
    	<origin xyz="0.026 -0.05 0" rpy="0 0 0" />
	</joint>
	
	<joint name="hair_joint" type="fixed">
    	<parent link="head_link" />
    	<child link="hair_link" />
    	<origin xyz="-0.025 0 0.0425" rpy="0 0 0" />
	</joint>
	
	<gazebo reference="kinectbot">
  	</gazebo>
</robot>

